<?xml version="1.0" encoding="utf-8"?>
<robot xmlns:xacro="http://www.ros.org/wiki/xacro">
<!-- This URDF was automatically created by SolidWorks to URDF Exporter! Originally created by Stephen Brawner (brawner@gmail.com) 
     Commit Version: 1.5.1-0-g916b5db  Build Version: 1.5.7152.31018
     For more information, please see http://wiki.ros.org/sw_urdf_exporter -->
  <xacro:macro name="single_arm" params="name parent *origin">   
    <link name="base_link0">
      <inertial>
        <origin
          xyz="0.000175438965895703 0.000532268611608213 0.0522669336069407"
          rpy="0 0 0" />
        <mass
          value="0.294119348658744" />
        <inertia
          ixx="0.00032400532756564"
          ixy="-5.40018128899478E-07"
          ixz="2.80958833443407E-06"
          iyy="0.000288426609563467"
          iyz="4.70285799717824E-06"
          izz="0.00022606419233657" />
      </inertial>
      <visual>
        <origin
          xyz="0 0 0"
          rpy="0 0 0" />
        <geometry>
          <mesh
            filename="package://single_arm_description/meshes/visual/base_link0.STL" />
        </geometry>
        <material
          name="">
          <color
            rgba="0.752941176470588 0.752941176470588 0.752941176470588 1" />
        </material>
      </visual>
      <collision>
        <origin
          xyz="0 0 0"
          rpy="0 0 0" />
        <geometry>
          <mesh
            filename="package://single_arm_description/meshes/collision/base_link0_simplified.STL" />
        </geometry>
      </collision>
    </link>
    
    <joint
      name="base_link0_joint" type="fixed">
      <parent link="${parent}" />
      <child link="base_link0" />
      <xacro:insert_block name="origin" />
      <axis xyz="0 0 1"/>
    </joint>

    <link
      name="Empty_Link1">
      <inertial>
        <origin
          xyz="-0.0698160338667713 0.0143691484806762 0.0110780451265005"
          rpy="0 0 0" />
        <mass
          value="0.0556965417664696" />
        <inertia
          ixx="2.70633960140179E-05"
          ixy="6.26519650974738E-06"
          ixz="-7.57900465240318E-06"
          iyy="0.000122679596314603"
          iyz="-1.35387556070585E-08"
          izz="0.000131443137410343" />
      </inertial>
      <visual>
        <origin
          xyz="0 0 0"
          rpy="0 0 0" />
        <geometry>
          <mesh
            filename="package://single_arm_description/meshes/visual/Empty_Link1.STL" />
        </geometry>
        <material
          name="">
          <color
            rgba="0.752941176470588 0.752941176470588 0.752941176470588 1" />
        </material>
      </visual>
      <collision>
        <origin
          xyz="0 0 0"
          rpy="0 0 0" />
        <geometry>
          <mesh
            filename="package://single_arm_description/meshes/collision/Empty_Link1_simplified.STL" />
        </geometry>
      </collision>
    </link>
    <joint
      name="joint1"
      type="revolute">
      <origin
        xyz="0 0 0.0962"
        rpy="0 0 0" />
      <parent
        link="base_link0" />
      <child
        link="Empty_Link1" />
      <axis
        xyz="0 0 1" />
      <limit
        lower="-3.14"
        upper="3.14"
        effort="0"
        velocity="0" />
    </joint>
    <link
      name="Empty_Link2">
      <inertial>
        <origin
          xyz="0.181439379971025 -0.000243727779993763 0.0563566127647854"
          rpy="0 0 0" />
        <mass
          value="0.136910629397679" />
        <inertia
          ixx="6.36253645667139E-05"
          ixy="-2.59780400404477E-07"
          ixz="3.91165512368072E-05"
          iyy="0.00232680960984668"
          iyz="2.19730518054456E-07"
          izz="0.00235460000620241" />
      </inertial>
      <visual>
        <origin
          xyz="0 0 0"
          rpy="0 0 0" />
        <geometry>
          <mesh
            filename="package://single_arm_description/meshes/visual/Empty_Link2.STL" />
        </geometry>
        <material
          name="">
          <color
            rgba="0.752941176470588 0.752941176470588 0.752941176470588 1" />
        </material>
      </visual>
      <collision>
        <origin
          xyz="0 0 0"
          rpy="0 0 0" />
        <geometry>
          <mesh
            filename="package://single_arm_description/meshes/collision/Empty_Link2_simplified.STL" />
        </geometry>
      </collision>
    </link>
    <joint
      name="joint2"
      type="revolute">
      <origin
        xyz="-0.0965 0 0"
        rpy="1.5708 -1.5708 0" />
      <parent
        link="Empty_Link1" />
      <child
        link="Empty_Link2" />
      <axis
        xyz="0 0 1" />
      <limit
        lower="-1.57"
        upper="1.57"
        effort="0"
        velocity="0" />
    </joint>
    <link
      name="Empty_Link3">
      <inertial>
        <origin
          xyz="0.0769703538179346 0.0011973381819983 -0.036630608037162"
          rpy="0 0 0" />
        <mass
          value="0.071034581827702" />
        <inertia
          ixx="2.84299236389363E-05"
          ixy="-7.63642211997418E-08"
          ixz="-3.24526804421142E-06"
          iyy="0.00034423782372923"
          iyz="7.76643137920171E-08"
          izz="0.000355286583426244" />
      </inertial>
      <visual>
        <origin
          xyz="0 0 0"
          rpy="0 0 0" />
        <geometry>
          <mesh
            filename="package://single_arm_description/meshes/visual/Empty_Link3.STL" />
        </geometry>
        <material
          name="">
          <color
            rgba="0.752941176470588 0.752941176470588 0.752941176470588 1" />
        </material>
      </visual>
      <collision>
        <origin
          xyz="0 0 0"
          rpy="0 0 0" />
        <geometry>
          <mesh
            filename="package://single_arm_description/meshes/collision/Empty_Link3_simplified.STL" />
        </geometry>
      </collision>
    </link>
    <joint
      name="joint3"
      type="revolute">
      <origin
        xyz="0.3465 0 0"
        rpy="0 0 0" />
      <parent
        link="Empty_Link2" />
      <child
        link="Empty_Link3" />
      <axis
        xyz="0 0 -1" />
      <limit
        lower="-2.44"
        upper="2.44"
        effort="0"
        velocity="0" />
    </joint>
    <link
      name="Empty_Link4">
      <inertial>
        <origin
          xyz="0.000159906636227225 -0.0237750547972229 0.0101176007477914"
          rpy="0 0 0" />
        <mass
          value="0.022184932643385" />
        <inertia
          ixx="2.56758689481119E-05"
          ixy="2.79874296577121E-08"
          ixz="5.63284180274909E-09"
          iyy="1.10340049734087E-05"
          iyz="-4.22353915692278E-06"
          izz="1.97133811530173E-05" />
      </inertial>
      <visual>
        <origin
          xyz="0 0 0"
          rpy="0 0 0" />
        <geometry>
          <mesh
            filename="package://single_arm_description/meshes/visual/Empty_Link4.STL" />
        </geometry>
        <material
          name="">
          <color
            rgba="0.752941176470588 0.752941176470588 0.752941176470588 1" />
        </material>
      </visual>
      <collision>
        <origin
          xyz="0 0 0"
          rpy="0 0 0" />
        <geometry>
          <mesh
            filename="package://single_arm_description/meshes/collision/Empty_Link4.STL" />
        </geometry>
      </collision>
    </link>
    <joint
      name="joint4"
      type="revolute">
      <origin
        xyz="0.15 0 0"
        rpy="0 0 3.1416" />
      <parent
        link="Empty_Link3" />
      <child
        link="Empty_Link4" />
      <axis
        xyz="0 0 1" />
      <limit
        lower="-2.61"
        upper="0.69"
        effort="0"
        velocity="0" />
    </joint>
    <link
      name="Empty_Link5">
      <inertial>
        <origin
          xyz="4.0073722048969E-05 0.0692610166439792 0.00106706924657128"
          rpy="0 0 0" />
        <mass
          value="0.0873760863924216" />
        <inertia
          ixx="0.000178750470884079"
          ixy="-5.70038950626815E-08"
          ixz="2.3383845024287E-08"
          iyy="8.0271837143644E-05"
          iyz="2.62896263229073E-06"
          izz="0.000152690614441042" />
      </inertial>
      <visual>
        <origin
          xyz="0 0 0"
          rpy="0 0 0" />
        <geometry>
          <mesh
            filename="package://single_arm_description/meshes/visual/Empty_Link5.STL" />
        </geometry>
        <material
          name="">
          <color
            rgba="0.752941176470588 0.752941176470588 0.752941176470588 1" />
        </material>
      </visual>
      <collision>
        <origin
          xyz="0 0 0"
          rpy="0 0 0" />
        <geometry>
          <mesh
            filename="package://single_arm_description/meshes/collision/Empty_Link5_simplified.STL" />
        </geometry>
      </collision>
    </link>
    <joint
      name="joint5"
      type="revolute">
      <origin
        xyz="0 -0.0965 0"
        rpy="1.5708 1.5708 3.1416" />
        <!-- rpy="1.5708 1.5708 0" /> -->
      <parent
        link="Empty_Link4" />
      <child
        link="Empty_Link5" />
      <axis
        xyz="0 0 -1" />
      <limit
        lower="-3.14"
        upper="3.14"
        effort="0"
        velocity="0" />
    </joint>
    <link
      name="Empty_Link6">
      <inertial>
        <origin
          xyz="1.77592382908782E-07 1.02533046673927E-07 0.00864548755955175"
          rpy="0 0 0" />
        <mass
          value="0.0269583221049951" />
        <inertia
          ixx="8.03963570266054E-06"
          ixy="7.7682030591729E-11"
          ixz="-6.48485539118529E-12"
          iyy="8.039546003178E-06"
          iyz="-3.74403298061715E-12"
          izz="1.53036652434403E-05" />
      </inertial>
      <visual>
        <origin
          xyz="0 0 0"
          rpy="0 0 0" />
        <geometry>
          <mesh
            filename="package://single_arm_description/meshes/visual/Empty_Link6.STL" />
        </geometry>
        <material
          name="">
          <color
            rgba="1 1 1 1" />
        </material>
      </visual>
      <collision>
        <origin
          xyz="0 0 0"
          rpy="0 0 0" />
        <geometry>
          <mesh
            filename="package://single_arm_description/meshes/collision/Empty_Link6_simplified.STL" />
        </geometry>
      </collision>
    </link>
    <joint
      name="joint6"
      type="revolute">
      <origin
        xyz="0 0.185 0"
        rpy="-1.5708 0 0" />
      <parent
        link="Empty_Link5" />
      <child
        link="Empty_Link6" />
      <axis
        xyz="0 0 -1" />
      <limit
        lower="-3.14"
        upper="3.14"
        effort="0"
        velocity="0" />
    </joint>
  </xacro:macro>
</robot>